<?xml version="1.0"?>
<robot name="slave" xmlns:xacro="http://ros.org/wiki/xacro">

	<xacro:macro name="default_inertia" params="mass">
		<inertial>
			<origin xyz="0 0 0" rpy="0 0 0"/>
			<mass value="${mass}" />
			<inertia ixx="0.1" ixy="0.0" ixz="0.0" iyy="0.1" iyz="0.0" izz="0.1"/>
		</inertial>
	</xacro:macro>

	<material name="white">
	    <color rgba="1 1 1 1"/>
	</material>

	<!-- Base Link -->
	<link name="base_link">
		<visual>
			<geometry>
				<box size="0.5 0.3 0.1"/>
			</geometry>
			<material name="white"/>
		</visual>
		<collision>
			<geometry>
				<box size="0.5 0.3 0.1"/>
			</geometry>
		</collision>
		<xacro:default_inertia mass="10"/>
	</link>


	<!-- Laser -->
	<link name="laser">
		<visual>
			<geometry>
				<cylinder length="0.3" radius="0.05"/>
			</geometry>
			<material name="white"/>
		</visual>
		<collision>
			<geometry>
				<cylinder length="0.3" radius="0.05"/>
			</geometry>
		</collision>
		<xacro:default_inertia mass="0.1"/>
	</link>

	<joint name="base_to_laser" type="fixed">
		<parent link="base_link"/>
		<child link="laser"/>
		<origin xyz="0 0 0.2"/>
	</joint>

	<!-- Depth Cam -->
	<link name="depth_cam_link">
		<visual>
			<geometry>
				<mesh filename="package://model/meshes/depth_cam.dae"/>
			</geometry>
			<material name="black"/>
		</visual>
		<collision>
			<geometry>
				<box size="0 0 0"/>
			</geometry>
		</collision>
		<xacro:default_inertia mass="0.1"/>
	</link>

	<joint name="base_to_cam" type="fixed">
		<parent link="base_link"/>
		<child link="depth_cam_link"/>
		<origin xyz="0.2 0 0.1"/>
	</joint>

	<!-- Wheels -->
	<xacro:macro name="wheel" params="name">
		<link name="${name}">
			<visual>
				<geometry>
					<cylinder length="0.1" radius="0.1"/>
				</geometry>
				<material name="black"/>
			</visual>
			<collision>
				<geometry>
					<cylinder length="0.1" radius="0.1"/>
				</geometry>
			</collision>
			<xacro:default_inertia mass="0.01"/>
		</link>
	</xacro:macro>

	<xacro:macro name="joint_wheel" params="child x y">
		<joint name="${child}_joint" type="continuous">
			<parent link="base_link"/>
			<child link="${child}"/>
			<origin xyz="${x} ${y} -0.1" rpy="-1.57075 0 0"/>
			<axis xyz="0 0 1"/>
		</joint>
	</xacro:macro>

	<xacro:wheel name="wheel_1"/>
	<xacro:joint_wheel child="wheel_1" x="0.2" y="0.3"/>

	<xacro:wheel name="wheel_2"/>
	<xacro:joint_wheel child="wheel_2" x="0.2" y="-0.3"/>


	<xacro:wheel name="wheel_3"/>
	<xacro:joint_wheel child="wheel_3" x="-0.1" y="0"/>

	 <!-- /Wheels -->

	<!-- LASER -->
	<joint name="hokuyo_joint" type="fixed">
		<axis xyz="0 1 0"/>
		<origin xyz="0 0 0.15"/>
		<parent link="laser"/>
		<child link="hokuyo_link"/>
	</joint>

	<!--Hokuyo Laser-->
	<link name="hokuyo_link">
		<collision>
			<origin xyz="0 0 0" rpy="0 0 0"/>
			<geometry>
				<box size="0.1 0.1 0.1"/>
			</geometry>
		</collision>
		<visual>
			<origin xyz="0 0 0" rpy="0 0 0"/>
			<geometry>
				<mesh filename="package://model/meshes/hokuyo.dae"/>
			</geometry>
		</visual>

		<inertial>
			<mass value="1e-5"/>
			<origin xyz="0 0 0" rpy="0 0 0"/>
			<inertia ixx="1e-6" ixy="1e-6" ixz="1e-6" iyy="1e-6" iyz="1e-6" izz="1e-6"/>
		</inertial>
	</link>

	<!-- hokuyo -->
	<gazebo reference="hokuyo_link">
		<sensor name="head_hokuyo_senser" type="ray">
			<pose>0 0 0 0 0 0</pose>
			<visualize>false</visualize>
			<update_rate>40</update_rate>
			<ray>
				<scan>
					<horizontal>
						<samples>720</samples>
						<resolution>1</resolution>
						<min_angle>-1.570796</min_angle>
						<max_angle>1.570796</max_angle>
					</horizontal>
				</scan>
				<range>
					<min>0.1</min>
					<max>30.0</max>
					<resolution>0.01</resolution>
				</range>
				<noise>
					<type>gaussian</type>
					<mean>0.0</mean>
					<stddev>0.01</stddev>
				</noise>
			</ray>
			<plugin name="gazebo_ros_head_hokuyo_controller" filename="libgazebo_ros_laser.so">
				<topicName>slave/laser/scan</topicName>
				<frameName>hokuyo_link</frameName>
			</plugin>
		</sensor>
	</gazebo>


	<!-- Depth Cam -->
	<gazebo reference="depth_cam_link">
		<sensor name="depth_cam_sensor" type="depth">
			<always_on>true</always_on>
			<update_rate>6.0</update_rate>
			<camera>
				<horizontal_fov>1.01229096616</horizontal_fov>
				<image>
					<format>R8G8B8</format>
					<widht>320</widht>
					<height>240</height>
				</image>
				<clip>
					<near>0.05</near>
					<far>4.0</far>
				</clip>
			</camera>
			<plugin filename="libgazebo_ros_openni_kinect.so" name="depth_cam_plugin">
				<alwaysOn>true</alwaysOn>
				<update_rate>6.0</update_rate>
				<cameraName>depth_cam</cameraName>
				<imageTopicName>ir/image_raw</imageTopicName>
				<cameraTopicName>ir/camera_info</cameraTopicName>
				<depthImageTopicName>depth/image_raw</depthImageTopicName>
				<depthImageCameraInfoTopicName>depth/camera_info</depthImageCameraInfoTopicName>
				<pointCloudTopicName>depth/points</pointCloudTopicName>
				<frameName>depth_cam_link</frameName>
				<pointCloudCutoff>0.05</pointCloudCutoff>
				<pointCloudCutoffMax>5</pointCloudCutoffMax>
				<rangeMax>4.0</rangeMax>
			</plugin>
		</sensor>
	</gazebo>


	<!-- Ros Control -->
	<gazebo>
		<plugin name="gazebo_ros_control" filename="libgazebo_ros_control.so">
			<robotNamespace>/slave</robotNamespace>
		</plugin>

		
		<plugin name="differential_drive_controller" filename="libgazebo_ros_diff_drive.so">
			<legacyMode>false</legacyMode>
			<alwaysOn>true</alwaysOn>
			<publishWhellTF>true</publishWhellTF>
			<publishTf>1</publishTf>
			<publishWheelJointState>true</publishWheelJointState>
			<updateRate>100.0</updateRate>
			<leftJoint>wheel_1_joint</leftJoint>
			<rightJoint>wheel_2_joint</rightJoint>
			<wheelSeparation>0.6</wheelSeparation>
			<wheelDiameter>0.2</wheelDiameter>
			<wheelAcceleration>1.0</wheelAcceleration>
			<torgue>20</torgue>
			<commandTopic>/slave/cmd_vel</commandTopic>
			<odometryTopic>odom</odometryTopic>
			<odometryFrame>odom</odometryFrame>
			<publishWheelTf>true</publishWheelTf>
			<robotBaseFrame>base_link</robotBaseFrame>
		</plugin>
		

	
	</gazebo>
</robot>
